<?xml version="1.0" ?>
<!-- =================================================================================== -->
<!-- |    This document was autogenerated by xacro from indy7.xacro                    | -->
<!-- |    EDITING THIS FILE BY HAND IS NOT RECOMMENDED                                 | -->
<!-- =================================================================================== -->
<robot name="scara" xmlns:xacro="http://ros.org/wiki/xacro">
  <link name="base_link">
    <visual>
      <origin rpy="0 0 0" xyz="0 0 0.1875"/>
      <geometry>
        <cylinder radius="0.05" length="0.375"/>
      </geometry>
     <material name="grey">
       <color rgba="0.5 0.5 0.5 0.5"/>
     </material>
    </visual>
    <visual>
      <origin rpy="0 0 0" xyz="0 0 0.025"/>
      <geometry>
        <cylinder radius="0.1" length="0.05"/>
      </geometry>
     <material name="grey">
       <color rgba="0.5 0.5 0.5 0.5"/>
     </material>
    </visual>    
  </link>
  <link name="link1">
    <visual>
      <origin rpy="0 0 0" xyz="0 0 0"/>
      <geometry>
        <cylinder radius="0.1" length="0.05"/>
      </geometry>
     <material name="grey">
       <color rgba="0.5 0.5 0.5 0.5"/>
     </material>      
    </visual>
    <visual>
      <origin rpy="0 0 0" xyz="0.0 0.25 0"/>
      <geometry>
        <box size="0.175 0.5 0.05"/>
      </geometry>
     <material name="grey">
       <color rgba="0.5 0.5 0.5 0.5"/>
     </material>      
    </visual>
  </link>
    <link name="link2">
    <visual>
      <origin rpy="0 0 0" xyz="0 0 0"/>
      <geometry>
        <cylinder radius="0.1" length="0.05"/>
      </geometry>
     <material name="grey">
       <color rgba="0.5 0.5 0.5 0.5"/>
     </material>      
    </visual>
    <visual>
      <origin rpy="0 0 0" xyz="0.25 0.0 0"/>
      <geometry>
        <box size="0.5 0.175 0.05"/>
      </geometry>
     <material name="grey">
       <color rgba="0.5 0.5 0.5 0.5"/>
     </material>      
    </visual>
  </link>

    <link name="link3">
    <visual>
      <origin rpy="0 0 0" xyz="0 0 0.1"/>
      <geometry>
        <cylinder radius="0.05" length="0.2"/>
      </geometry>
     <material name="grey">
       <color rgba="0.5 0.5 0.5 0.5"/>
     </material>      
    </visual>
    <visual>
      <origin rpy="0 0 0" xyz="0 0 -0.125"/>
      <geometry>
        <cylinder radius="0.025" length="0.25"/>
      </geometry>
     <material name="grey">
       <color rgba="0.5 0.5 0.5 0.5"/>
     </material>      
    </visual>    
  </link>
    <link name="link4">
    <visual>
      <origin rpy="0 0 0" xyz="0 0 0.0"/>
      <geometry>
        <box size="0.1 0.1 0.1"/>
      </geometry>
     <material name="grey">
       <color rgba="0.5 0.5 0.5 0.5"/>
     </material>      
    </visual>

  </link>
    <link name="tcp">
  </link>
<link name="world"/>
    <joint name="world_fixed" type="fixed">
          <parent link="world"/>
    <child link="base_link"/>
    </joint>
  <joint name="joint0" type="revolute">
    <parent link="base_link"/>
    <child link="link1"/>
    <origin rpy="0 0 0" xyz="0.0 0.0 0.375"/>
    <axis xyz="0 0 1"/>
    <limit effort="10" lower="-3.05432619099" upper="3.05432619099" velocity="1"/>
  </joint>

  <joint name="joint1" type="revolute">
    <parent link="link1"/>
    <child link="link2"/>
    <origin rpy="0.0175	0.0175	-0.0175" xyz="0.01	0.51	-0.024"/>
    <axis xyz="0 0 1"/>
    <limit effort="10"  velocity="1"/>
  </joint>  

  <joint name="joint2" type="revolute">
    <parent link="link2"/>
    <child link="link3"/>
    <origin rpy="0.0175	-0.0175	0.0175" xyz="0.51	-0.01	0.01"/>
    <axis xyz="0 0 1"/>
    <limit effort="10"  velocity="1"/>
  </joint>    
  <joint name="joint3" type="prismatic">
    <parent link="link3"/>
    <child link="link4"/>
    <origin rpy="-0.0175	-0.0175	-0.0175" xyz="-0.01	-0.01	-0.29"/>
    <axis xyz="0 0 -1"/>
    <limit effort="10"  velocity="1"/>
  </joint>      

  <joint name="tcp_fixed" type="fixed">
    <parent link="link4"/>
    <child link="tcp"/>
    <origin rpy="0 0 0" xyz="0.0 0.0 0"/>
  </joint>        
</robot>

